Workbook

Sheet LAA & MILP
A1: case | B1: seed | C1: nV | D1: uvl | E1: fsd | F1: N | G1: dc | H1: charging_speed | I1: dwl | J1: ad | K1: OBJ_LB | L1: OBJ_LAA | M1: OBJ_MILP | N1: CPU_time_LAA | O1: CPU_time_MILP | P1: RD_LAA_to_LB(%) | Q1: RD_LAA_to_MILP(%)
A2: 0 | B2: 1 | C2: 25 | D2: 0.005 | E2: 1 | F2: 1 | G2: 3 | H2: 0.0333 | I2: 30 | J2: 50 | K2: =LAA!O2 -> 42.455 | L2: =LAA!K2 -> 42.455 | M2: =MILP!K2 -> 42.455 | N2: =LAA!P2 -> 0.0038464069 | O2: =MILP!L2 -> 0.0091 | P2: =(L2-K2)/K2 -> 0 | Q2: =(L2-M2)/M2 -> 0
A3: 1 | B3: 1 | C3: 25 | D3: 0.005 | E3: 1 | F3: 2 | G3: 3 | H3: 0.0333 | I3: 30 | J3: 50 | K3: =LAA!O3 -> 40.6215 | L3: =LAA!K3 -> 40.8475 | M3: =MILP!K3 -> 40.838 | N3: =LAA!P3 -> 0.13871861 | O3: =MILP!L3 -> 0.0754 | P3: =(L3-K3)/K3 -> 0.0055635562 | Q3: =(L3-M3)/M3 -> 0.00023262648
A4: 2 | B4: 1 | C4: 25 | D4: 0.005 | E4: 1 | F4: 3 | G4: 3 | H4: 0.0333 | I4: 30 | J4: 50 | K4: =LAA!O4 -> 40.2885 | L4: =LAA!K4 -> 40.469 | M4: =MILP!K4 -> 40.4995 | N4: =LAA!P4 -> 0.20905256 | O4: =MILP!L4 -> 0.0972 | P4: =(L4-K4)/K4 -> 0.0044801867 | Q4: =(L4-M4)/M4 -> -0.00075309572
A5: 3 | B5: 1 | C5: 25 | D5: 0.005 | E5: 1 | F5: 4 | G5: 3 | H5: 0.0333 | I5: 30 | J5: 50 | K5: =LAA!O5 -> 40.153 | L5: =LAA!K5 -> 40.199 | M5: =MILP!K5 -> 40.26 | N5: =LAA!P5 -> 0.16676259 | O5: =MILP!L5 -> 0.0791 | P5: =(L5-K5)/K5 -> 0.001145618 | Q5: =(L5-M5)/M5 -> -0.0015151515
A6: 4 | B6: 1 | C6: 25 | D6: 0.005 | E6: 1 | F6: 5 | G6: 3 | H6: 0.0333 | I6: 30 | J6: 50 | K6: =LAA!O6 -> 40.153 | L6: =LAA!K6 -> 40.199 | M6: =MILP!K6 -> 40.26 | N6: =LAA!P6 -> 0.10449004 | O6: =MILP!L6 -> 0.0822 | P6: =(L6-K6)/K6 -> 0.001145618 | Q6: =(L6-M6)/M6 -> -0.0015151515
A7: 5 | B7: 1 | C7: 25 | D7: 0.005 | E7: 1 | F7: 6 | G7: 3 | H7: 0.0333 | I7: 30 | J7: 50 | K7: =LAA!O7 -> 40.153 | L7: =LAA!K7 -> 40.199 | M7: =MILP!K7 -> 40.26 | N7: =LAA!P7 -> 0.24077296 | O7: =MILP!L7 -> 0.0827 | P7: =(L7-K7)/K7 -> 0.001145618 | Q7: =(L7-M7)/M7 -> -0.0015151515
A8: 6 | B8: 1 | C8: 25 | D8: 0.005 | E8: 1 | F8: 7 | G8: 3 | H8: 0.0333 | I8: 30 | J8: 50 | K8: =LAA!O8 -> 40.153 | L8: =LAA!K8 -> 40.199 | M8: =MILP!K8 -> 40.26 | N8: =LAA!P8 -> 0.17099285 | O8: =MILP!L8 -> 0.0828 | P8: =(L8-K8)/K8 -> 0.001145618 | Q8: =(L8-M8)/M8 -> -0.0015151515
A9: 7 | B9: 1 | C9: 25 | D9: 0.005 | E9: 1 | F9: 8 | G9: 3 | H9: 0.0333 | I9: 30 | J9: 50 | K9: =LAA!O9 -> 40.153 | L9: =LAA!K9 -> 40.199 | M9: =MILP!K9 -> 40.26 | N9: =LAA!P9 -> 0.18987894 | O9: =MILP!L9 -> 0.0821 | P9: =(L9-K9)/K9 -> 0.001145618 | Q9: =(L9-M9)/M9 -> -0.0015151515
A10: 8 | B10: 1 | C10: 25 | D10: 0.005 | E10: 1 | F10: 9 | G10: 3 | H10: 0.0333 | I10: 30 | J10: 50 | K10: =LAA!O10 -> 40.153 | L10: =LAA!K10 -> 40.199 | M10: =MILP!K10 -> 40.26 | N10: =LAA!P10 -> 0.11633158 | O10: =MILP!L10 -> 0.0824 | P10: =(L10-K10)/K10 -> 0.001145618 | Q10: =(L10-M10)/M10 -> -0.0015151515
A11: 9 | B11: 1 | C11: 25 | D11: 0.005 | E11: 1 | F11: 10 | G11: 3 | H11: 0.0333 | I11: 30 | J11: 50 | K11: =LAA!O11 -> 40.153 | L11: =LAA!K11 -> 40.199 | M11: =MILP!K11 -> 40.26 | N11: =LAA!P11 -> 0.23114824 | O11: =MILP!L11 -> 0.0824 | P11: =(L11-K11)/K11 -> 0.001145618 | Q11: =(L11-M11)/M11 -> -0.0015151515
A12: 10 | B12: 1 | C12: 25 | D12: 0.005 | E12: 1 | F12: 10 | G12: 3 | H12: 0.0333 | I12: 30 | J12: 40 | K12: =LAA!O12 -> 40.153 | L12: =LAA!K12 -> 40.2215 | M12: =MILP!K12 -> 40.179 | N12: =LAA!P12 -> 0.20057607 | O12: =MILP!L12 -> 0.0804 | P12: =(L12-K12)/K12 -> 0.0017059746 | Q12: =(L12-M12)/M12 -> 0.0010577665
A13: 11 | B13: 1 | C13: 25 | D13: 0.005 | E13: 1 | F13: 10 | G13: 3 | H13: 0.0333 | I13: 30 | J13: 30 | K13: =LAA!O13 -> 40.164 | L13: =LAA!K13 -> 40.2245 | M13: =MILP!K13 -> 40.2095 | N13: =LAA!P13 -> 0.40441895 | O13: =MILP!L13 -> 0.2437 | P13: =(L13-K13)/K13 -> 0.0015063241 | Q13: =(L13-M13)/M13 -> 0.00037304617
... A242: 240 | B242: 3 | C242: 100 | D242: 0.005 | E242: 1 | F242: 10 | G242: 3 | H242: 0.0333 | I242: 30 | J242: 20 | K242: =LAA!O242 -> 158.4305 | L242: =LAA!K242 -> 160.33 | M242: =MILP!K242 -> 167.026 | N242: =LAA!P242 -> 5.6816952 | O242: =MILP!L242 -> 3600.197 | P242: =(L242-K242)/K242 -> 0.011989484 | Q242: =(L242-M242)/M242 -> -0.040089567
A243: 241 | B243: 3 | C243: 100 | D243: 0.005 | E243: 1 | F243: 10 | G243: 3 | H243: 0.0333 | I243: 30 | J243: 10 | K243: =LAA!O243 -> 158.3905 | L243: =LAA!K243 -> 160.4125 | N243: =LAA!P243 -> 25.892228 | P243: =(L243-K243)/K243 -> 0.012765917
A244: 242 | B244: 3 | C244: 100 | D244: 0.005 | E244: 1 | F244: 10 | G244: 2 | H244: 0.0333 | I244: 30 | J244: 50 | K244: =LAA!O244 -> 158.542 | L244: =LAA!K244 -> 160.073 | M244: =MILP!K244 -> 159.6425 | N244: =LAA!P244 -> 1.3077416 | P244: =(L244-K244)/K244 -> 0.0096567471 | Q244: =(L244-M244)/M244 -> 0.0026966505
A245: 243 | B245: 3 | C245: 100 | D245: 0.005 | E245: 1 | F245: 10 | G245: 1 | H245: 0.0333 | I245: 30 | J245: 50 | K245: =LAA!O245 -> 158.3055 | L245: =LAA!K245 -> 159.7625 | M245: =MILP!K245 -> 159.13 | N245: =LAA!P245 -> 0.94654751 | P245: =(L245-K245)/K245 -> 0.0092037232 | Q245: =(L245-M245)/M245 -> 0.0039747378
A246: 244 | B246: 3 | C246: 100 | D246: 0.005 | E246: 1 | F246: 10 | G246: 3 | H246: 0.0333 | I246: 60 | J246: 50 | K246: =LAA!O246 -> 157.5135 | L246: =LAA!K246 -> 157.8805 | M246: =MILP!K246 -> 158.652 | N246: =LAA!P246 -> 0.559062 | P246: =(L246-K246)/K246 -> 0.002329959 | Q246: =(L246-M246)/M246 -> -0.0048628445
A247: 245 | B247: 3 | C247: 100 | D247: 0.005 | E247: 1 | F247: 10 | G247: 3 | H247: 0.0333 | I247: 90 | J247: 50 | K247: =LAA!O247 -> 157.4195 | L247: =LAA!K247 -> 157.567 | M247: =MILP!K247 -> 157.9745 | N247: =LAA!P247 -> 0.43020082 | P247: =(L247-K247)/K247 -> 0.00093698684 | Q247: =(L247-M247)/M247 -> -0.0025795302
A248: 246 | B248: 3 | C248: 100 | D248: 0.005 | E248: 1 | F248: 10 | G248: 3 | H248: 0.0333 | I248: 120 | J248: 50 | K248: =LAA!O248 -> 157.275 | L248: =LAA!K248 -> 157.432 | M248: =MILP!K248 -> 157.772 | N248: =LAA!P248 -> 0.42901206 | P248: =(L248-K248)/K248 -> 0.00099825147 | Q248: =(L248-M248)/M248 -> -0.0021550085
A249: 247 | B249: 4 | C249: 100 | D249: 0.005 | E249: 1 | F249: 1 | G249: 3 | H249: 0.0333 | I249: 30 | J249: 50 | K249: =LAA!O249 -> 165.525 | L249: =LAA!K249 -> 165.525 | M249: =MILP!K249 -> 165.525 | N249: =LAA!P249 -> 0.015669823 | P249: =(L249-K249)/K249 -> 0 | Q249: =(L249-M249)/M249 -> -6.0097256e-15
A250: 248 | B250: 4 | C250: 100 | D250: 0.005 | E250: 1 | F250: 2 | G250: 3 | H250: 0.0333 | I250: 30 | J250: 50 | K250: =LAA!O250 -> 157.2855 | L250: =LAA!K250 -> 157.435 | M250: =MILP!K250 -> 157.4305 | N250: =LAA!P250 -> 0.37368703 | P250: =(L250-K250)/K250 -> 0.00095050084 | Q250: =(L250-M250)/M250 -> 2.8587489e-05
A251: 249 | B251: 4 | C251: 100 | D251: 0.005 | E251: 1 | F251: 3 | G251: 3 | H251: 0.0333 | I251: 30 | J251: 50 | K251: =LAA!O251 -> 154.658 | L251: =LAA!K251 -> 155.001 | M251: =MILP!K251 -> 154.79 | N251: =LAA!P251 -> 0.52111626 | P251: =(L251-K251)/K251 -> 0.0022177967 | Q251: =(L251-M251)/M251 -> 0.0013631373
A252: 250 | B252: 4 | C252: 100 | D252: 0.005 | E252: 1 | F252: 4 | G252: 3 | H252: 0.0333 | I252: 30 | J252: 50 | K252: =LAA!O252 -> 153.31 | L252: =LAA!K252 -> 153.9105 | M252: =MILP!K252 -> 153.933 | N252: =LAA!P252 -> 0.63662243 | P252: =(L252-K252)/K252 -> 0.0039169004 | Q252: =(L252-M252)/M252 -> -0.00014616749
A253: 251 | B253: 4 | C253: 100 | D253: 0.005 | E253: 1 | F253: 5 | G253: 3 | H253: 0.0333 | I253: 30 | J253: 50 | K253: =LAA!O253 -> 152.591 | L253: =LAA!K253 -> 153.218 | M253: =MILP!K253 -> 153.3225 | N253: =LAA!P253 -> 0.73692012 | P253: =(L253-K253)/K253 -> 0.0041090235 | Q253: =(L253-M253)/M253 -> -0.0006815696
A254: 252 | B254: 4 | C254: 100 | D254: 0.005 | E254: 1 | F254: 6 | G254: 3 | H254: 0.0333 | I254: 30 | J254: 50 | K254: =LAA!O254 -> 152.152 | L254: =LAA!K254 -> 152.8475 | M254: =MILP!K254 -> 152.7625 | N254: =LAA!P254 -> 0.74789047 | P254: =(L254-K254)/K254 -> 0.0045710868 | Q254: =(L254-M254)/M254 -> 0.00055641937
A255: 253 | B255: 4 | C255: 100 | D255: 0.005 | E255: 1 | F255: 7 | G255: 3 | H255: 0.0333 | I255: 30 | J255: 50 | K255: =LAA!O255 -> 151.873 | L255: =LAA!K255 -> 152.7585 | M255: =MILP!K255 -> 152.8195 | N255: =LAA!P255 -> 0.77728438 | P255: =(L255-K255)/K255 -> 0.0058305295 | Q255: =(L255-M255)/M255 -> -0.00039916372
... A261: 259 | B261: 4 | C261: 100 | D261: 0.005 | E261: 1 | F261: 10 | G261: 3 | H261: 0.0333 | I261: 30 | J261: 20 | K261: =LAA!O261 -> 151.5565 | L261: =LAA!K261 -> 153.275 | M261: =MILP!K261 -> 161.57 | N261: =LAA!P261 -> 4.8714008 | P261: =(L261-K261)/K261 -> 0.011339006 | Q261: =(L261-M261)/M261 -> -0.051339976
A262: 260 | B262: 4 | C262: 100 | D262: 0.005 | E262: 1 | F262: 10 | G262: 3 | H262: 0.0333 | I262: 30 | J262: 10 | K262: =LAA!O262 -> 151.507 | L262: =LAA!K262 -> 153.4545 | N262: =LAA!P262 -> 19.978861 | P262: =(L262-K262)/K262 -> 0.012854192
A263: 261 | B263: 4 | C263: 100 | D263: 0.005 | E263: 1 | F263: 10 | G263: 2 | H263: 0.0333 | I263: 30 | J263: 50 | K263: =LAA!O263 -> 151.57 | L263: =LAA!K263 -> 152.823 | M263: =MILP!K263 -> 152.274 | N263: =LAA!P263 -> 1.0448546 | P263: =(L263-K263)/K263 -> 0.0082668074 | Q263: =(L263-M263)/M263 -> 0.003605343
A264: 262 | B264: 4 | C264: 100 | D264: 0.005 | E264: 1 | F264: 10 | G264: 1 | H264: 0.0333 | I264: 30 | J264: 50 | K264: =LAA!O264 -> 151.502 | L264: =LAA!K264 -> 152.945 | M264: =MILP!K264 -> 152.322 | N264: =LAA!P264 -> 0.9380188 | P264: =(L264-K264)/K264 -> 0.0095246267 | Q264: =(L264-M264)/M264 -> 0.0040900198
A265: 263 | B265: 4 | C265: 100 | D265: 0.005 | E265: 1 | F265: 10 | G265: 3 | H265: 0.0333 | I265: 60 | J265: 50 | K265: =LAA!O265 -> 150.802 | L265: =LAA!K265 -> 151.244 | M265: =MILP!K265 -> 151.7705 | N265: =LAA!P265 -> 0.47201705 | P265: =(L265-K265)/K265 -> 0.0029309956 | Q265: =(L265-M265)/M265 -> -0.0034690536
A266: 264 | B266: 4 | C266: 100 | D266: 0.005 | E266: 1 | F266: 10 | G266: 3 | H266: 0.0333 | I266: 90 | J266: 50 | K266: =LAA!O266 -> 150.7035 | L266: =LAA!K266 -> 150.835 | M266: =MILP!K266 -> 151.309 | N266: =LAA!P266 -> 0.45893288 | P266: =(L266-K266)/K266 -> 0.00087257429 | Q266: =(L266-M266)/M266 -> -0.0031326623
A267: 265 | B267: 4 | C267: 100 | D267: 0.005 | E267: 1 | F267: 10 | G267: 3 | H267: 0.0333 | I267: 120 | J267: 50 | K267: =LAA!O267 -> 150.672 | L267: =LAA!K267 -> 150.722 | M267: =MILP!K267 -> 151.095 | N267: =LAA!P267 -> 0.41672301 | P267: =(L267-K267)/K267 -> 0.00033184666 | Q267: =(L267-M267)/M267 -> -0.0024686456
A268: 266 | B268: 5 | C268: 100 | D268: 0.005 | E268: 1 | F268: 1 | G268: 3 | H268: 0.0333 | I268: 30 | J268: 50 | K268: =LAA!O268 -> 187.49 | L268: =LAA!K268 -> 187.49 | M268: =MILP!K268 -> 187.49 | N268: =LAA!P268 -> 0.01731801 | P268: =(L268-K268)/K268 -> 0 | Q268: =(L268-M268)/M268 -> 0
A269: 267 | B269: 5 | C269: 100 | D269: 0.005 | E269: 1 | F269: 2 | G269: 3 | H269: 0.0333 | I269: 30 | J269: 50 | K269: =LAA!O269 -> 178.1965 | L269: =LAA!K269 -> 178.319 | M269: =MILP!K269 -> 178.353 | N269: =LAA!P269 -> 0.57621646 | P269: =(L269-K269)/K269 -> 0.00068744336 | Q269: =(L269-M269)/M269 -> -0.00019063318
A270: 268 | B270: 5 | C270: 100 | D270: 0.005 | E270: 1 | F270: 3 | G270: 3 | H270: 0.0333 | I270: 30 | J270: 50 | K270: =LAA!O270 -> 175.2355 | L270: =LAA!K270 -> 175.4825 | M270: =MILP!K270 -> 175.594 | N270: =LAA!P270 -> 0.48157668 | P270: =(L270-K270)/K270 -> 0.0014095317 | Q270: =(L270-M270)/M270 -> -0.00063498741
A271: 269 | B271: 5 | C271: 100 | D271: 0.005 | E271: 1 | F271: 4 | G271: 3 | H271: 0.0333 | I271: 30 | J271: 50 | K271: =LAA!O271 -> 173.77 | L271: =LAA!K271 -> 174.4315 | M271: =MILP!K271 -> 174.3455 | N271: =LAA!P271 -> 0.58880019 | P271: =(L271-K271)/K271 -> 0.0038067561 | Q271: =(L271-M271)/M271 -> 0.00049327341
A272: 270 | B272: 5 | C272: 100 | D272: 0.005 | E272: 1 | F272: 5 | G272: 3 | H272: 0.0333 | I272: 30 | J272: 50 | K272: =LAA!O272 -> 172.92 | L272: =LAA!K272 -> 173.793 | M272: =MILP!K272 -> 173.7725 | N272: =LAA!P272 -> 0.63617229 | P272: =(L272-K272)/K272 -> 0.0050485774 | Q272: =(L272-M272)/M272 -> 0.00011797091
A273: 271 | B273: 5 | C273: 100 | D273: 0.005 | E273: 1 | F273: 6 | G273: 3 | H273: 0.0333 | I273: 30 | J273: 50 | K273: =LAA!O273 -> 172.4135 | L273: =LAA!K273 -> 173.51 | M273: =MILP!K273 -> 173.443 | N273: =LAA!P273 -> 0.73618245 | P273: =(L273-K273)/K273 -> 0.0063597108 | Q273: =(L273-M273)/M273 -> 0.00038629406
...

Sheet Var Explanation
A1: Parameter Description and Data Source
A3: Seed / Seed ID: Controls randomness for reproducibility.
A4: (uvl) % of Follower Energy Reduction: Assumed energy savings for follower vehicles (e.g., a follower consumes 1% less energy than the leader).
A5: (N) Maximum Platoon Size: Upper limit on the number of vehicles in a platoon.
A6: (cs) Charging speed
A7: (nV) Number of Vehicles: Total vehicles traveling on the highway, derived from input data (e.g., arrival times and trip details).
A8: (fsd) Fraction of Short-Distance Vehicles: Determines the proportion of short- vs long-distance vehicles (e.g., 0 → 25% short-distance, 1 → 50%, 2 → 75%).
A9: (dc) Charging Point Frequency: Defines how often charging stations appear relative to platoon points (e.g., 1: every point, 2: every two points, etc.).
A10: (ad) Average Distance: Average spacing between platoon points, based on the dataset.
A11: (dwl) Due Window Length: Additional allowable travel time (minute) for vehicles, derived from input conditions.
A12: OBJ_LB: Lower bound of objective value
A13: OBJ_LAA: Objective value obtain from Look Ahead Algorithm method
... A17: (RD_LAA_to_MILP(%)): Relative difference of LAA's objective value to MILP's objective value

Sheet Average
A1: case | B1: seed | C1: nV | D1: uvl | E1: fsd | F1: N | G1: dc | H1: charging_speed | I1: dwl | J1: ad | K1: OBJ_MILP | L1: OBJ_LAA | M1: OBJ_LB | N1: CPU_MILP | O1: CPU_LLA | P1: MILP GAP | Q1: RD MILP to LB | R1: RD LLA to MILP | S1: RD LLA to LB | T1: Ered | V1: OBJ_LAA | W1: OBJ_IPFA_F | X1: OBJ_IPFA_B | Y1: OBJ_LB | Z1: CPU_LAA | AA1: CPU_IPFA_F | AB1: CPU_IPFA_B | AC1: 'rd2LB' | AD1: 'rd2MILP' | AE1: 'rdMILP2LB' | AF1: OBJ_MILP | AG1: 'CPU MILP' | AH1: 'GAP MILP' | AI1: max_CPULLA | AJ1: max_CPUF | AK1: max_RD | AL1: OBJ_alone
A2: 0 | B2: 1 | C2: 25 | D2: 0.005 | E2: 1 | F2: 1 | G2: 3 | H2: 0.0333 | I2: 30 | J2: 50 | K2: 44.162 | L2: 44.162 | M2: 44.162 | N2: 0.0142 | O2: 0.0405 | P2: 0 | Q2: 0 | R2: 0 | S2: 0 | T2: 0 | V2: 44.162 | W2: 44.162 | X2: 44.162 | Y2: 44.162 | Z2: 0.0405 | AA2: 0.0002 | AB2: 0.0075 | AC2: 0 | AD2: 0 | AE2: 0 | AF2: 44.162 | AG2: 0.0142 | AH2: 0 | AI2: 47.825 | AJ2: 0.0489 | AK2: 0.001 | AL2: =IF(F2=1,V2,AL1) -> 44.162
A3: =A2+1 -> 1 | B3: 1 | C3: 25 | D3: 0.005 | E3: 1 | F3: 2 | G3: 3 | H3: 0.0333 | I3: 30 | J3: 50 | K3: 42.3512 | L3: 42.2882 | M3: 42.23 | N3: 2.5728 | O3: 0.0318 | P3: 0 | Q3: 0.0029 | R3: -0.0015 | S3: 0.0014 | T3: 0.042430144 | V3: 42.2882 | W3: 42.3394 | X3: 42.3616 | Y3: 42.23 | Z3: 0.0318 | AA3: 0.0008 | AB3: 0.0022 | AC3: 0.0014 | AD3: -0.0015 | AE3: 0.0029 | AF3: 42.3512 | AG3: 2.5728 | AH3: 0 | AI3: 45.7725 | AJ3: 0.064 | AK3: 0.0022 | AL3: =IF(F3=1,V3,AL2) -> 44.162
A4: =A3+1 -> 2 | B4: 1 | C4: 25 | D4: 0.005 | E4: 1 | F4: 3 | G4: 3 | H4: 0.0333 | I4: 30 | J4: 50 | K4: 41.9298 | L4: 41.8848 | M4: 41.7814 | N4: 96.3327 | O4: 0.0311 | P4: 0 | Q4: 0.0035 | R4: -0.001 | S4: 0.0025 | T4: 0.051564694 | V4: 41.8848 | W4: 41.921 | X4: 42.0237 | Y4: 41.7814 | Z4: 0.0311 | AA4: 0.0091 | AB4: 0.0007 | AC4: 0.0025 | AD4: -0.001 | AE4: 0.0035 | AF4: 41.9298 | AG4: 96.3327 | AH4: 0 | AI4: 45.1935 | AJ4: 0.0458 | AK4: 0.0157 | AL4: =IF(F4=1,V4,AL3) -> 44.162
A5: =A4+1 -> 3 | B5: 1 | C5: 25 | D5: 0.005 | E5: 1 | F5: 4 | G5: 3 | H5: 0.0333 | I5: 30 | J5: 50 | K5: 41.8178 | L5: 41.7779 | M5: 41.6153 | N5: 35.6741 | O5: 0.0401 | P5: 0 | Q5: 0.0048 | R5: -0.0009 | S5: 0.0039 | T5: 0.053985327 | V5: 41.7779 | W5: 41.8258 | X5: 41.8908 | Y5: 41.6153 | Z5: 0.0401 | AA5: 0.004 | AB5: 0.0058 | AC5: 0.0039 | AD5: -0.0009 | AE5: 0.0048 | AF5: 41.8178 | AG5: 35.6741 | AH5: 0 | AI5: 44.982 | AJ5: 0.0586 | AK5: 0.0157 | AL5: =IF(F5=1,V5,AL4) -> 44.162
A6: =A5+1 -> 4 | B6: 1 | C6: 25 | D6: 0.005 | E6: 1 | F6: 5 | G6: 3 | H6: 0.0333 | I6: 30 | J6: 50 | K6: 41.7523 | L6: 41.7622 | M6: 41.5642 | N6: 7.3993 | O6: 0.034 | P6: 0 | Q6: 0.0045 | R6: 0.0003 | S6: 0.0047 | T6: 0.054340836 | V6: 41.7622 | W6: 41.8141 | X6: 41.8181 | Y6: 41.5642 | Z6: 0.034 | AA6: 0.0013 | AB6: 0.0016 | AC6: 0.0047 | AD6: 0.0003 | AE6: 0.0045 | AF6: 41.7523 | AG6: 7.3993 | AH6: 0 | AI6: 44.982 | AJ6: 0.0554 | AK6: 0.0035 | AL6: =IF(F6=1,V6,AL5) -> 44.162
A7: =A6+1 -> 5 | B7: 1 | C7: 25 | D7: 0.005 | E7: 1 | F7: 6 | G7: 3 | H7: 0.0333 | I7: 30 | J7: 50 | K7: 41.7523 | L7: 41.7622 | M7: 41.5556 | N7: 5.7044 | O7: 0.0304 | P7: 0 | Q7: 0.0047 | R7: 0.0003 | S7: 0.0049 | T7: 0.054340836 | V7: 41.7622 | W7: 41.8141 | X7: 41.8181 | Y7: 41.5556 | Z7: 0.0304 | AA7: 0.0032 | AB7: 0.0032 | AC7: 0.0049 | AD7: 0.0003 | AE7: 0.0047 | AF7: 41.7523 | AG7: 5.7044 | AH7: 0 | AI7: 44.982 | AJ7: 0.0493 | AK7: 0.01 | AL7: =IF(F7=1,V7,AL6) -> 44.162
A8: =A7+1 -> 6 | B8: 1 | C8: 25 | D8: 0.005 | E8: 1 | F8: 7 | G8: 3 | H8: 0.0333 | I8: 30 | J8: 50 | K8: 41.7523 | L8: 41.7622 | M8: 41.5556 | N8: 4.5046 | O8: 0.0307 | P8: 0 | Q8: 0.0047 | R8: 0.0003 | S8: 0.0049 | T8: 0.054340836 | V8: 41.7622 | W8: 41.8141 | X8: 41.8181 | Y8: 41.5556 | Z8: 0.0307 | AA8: 0.001 | AB8: 0.0052 | AC8: 0.0049 | AD8: 0.0003 | AE8: 0.0047 | AF8: 41.7523 | AG8: 4.5046 | AH8: 0 | AI8: 44.982 | AJ8: 0.0342 | AK8: 0.0031 | AL8: =IF(F8=1,V8,AL7) -> 44.162
A9: =A8+1 -> 7 | B9: 1 | C9: 25 | D9: 0.005 | E9: 1 | F9: 8 | G9: 3 | H9: 0.0333 | I9: 30 | J9: 50 | K9: 41.7523 | L9: 41.7622 | M9: 41.5556 | N9: 5.0546 | O9: 0.0379 | P9: 0 | Q9: 0.0047 | R9: 0.0003 | S9: 0.0049 | T9: 0.054340836 | V9: 41.7622 | W9: 41.8141 | X9: 41.8181 | Y9: 41.5556 | Z9: 0.0379 | AA9: 0.0008 | AB9: 0.0024 | AC9: 0.0049 | AD9: 0.0003 | AE9: 0.0047 | AF9: 41.7523 | AG9: 5.0546 | AH9: 0 | AI9: 44.982 | AJ9: 0.0462 | AK9: 0.002 | AL9: =IF(F9=1,V9,AL8) -> 44.162
A10: =A9+1 -> 8 | B10: 1 | C10: 25 | D10: 0.005 | E10: 1 | F10: 9 | G10: 3 | H10: 0.0333 | I10: 30 | J10: 50 | K10: 41.7523 | L10: 41.7622 | M10: 41.5556 | N10: 5.0814 | O10: 0.0312 | P10: 0 | Q10: 0.0047 | R10: 0.0003 | S10: 0.0049 | T10: 0.054340836 | V10: 41.7622 | W10: 41.8141 | X10: 41.8181 | Y10: 41.5556 | Z10: 0.0312 | AA10: 0.0016 | AB10: 0.0054 | AC10: 0.0049 | AD10: 0.0003 | AE10: 0.0047 | AF10: 41.7523 | AG10: 5.0814 | AH10: 0 | AI10: 44.982 | AJ10: 0.0397 | AK10: 0.0031 | AL10: =IF(F10=1,V10,AL9) -> 44.162
A11: =A10+1 -> 9 | B11: 1 | C11: 25 | D11: 0.005 | E11: 1 | F11: 10 | G11: 3 | H11: 0.0333 | I11: 30 | J11: 50 | K11: 41.7523 | L11: 41.7622 | M11: 41.5556 | N11: 5.0384 | O11: 0.0303 | P11: 0 | Q11: 0.0047 | R11: 0.0003 | S11: 0.0049 | T11: 0.054340836 | V11: 41.7622 | W11: 41.8141 | X11: 41.8181 | Y11: 41.5556 | Z11: 0.0303 | AA11: 0.0008 | AB11: 0.0006 | AC11: 0.0049 | AD11: 0.0003 | AE11: 0.0047 | AF11: 41.7523 | AG11: 5.0384 | AH11: 0 | AI11: 44.982 | AJ11: 0.0421 | AK11: 0.003 | AL11: =IF(F11=1,V11,AL10) -> 44.162
A12: =A11+1 -> 10 | B12: 1 | C12: 25 | D12: 0.005 | E12: 1 | F12: 10 | G12: 3 | H12: 0.0333 | I12: 30 | J12: 40 | K12: 41.7422 | L12: 41.7625 | M12: 41.5625 | N12: 6.1368 | O12: 0.0509 | P12: 0 | Q12: 0.0042 | R12: 0.0006 | S12: 0.0048 | T12: 0.054334043 | V12: 41.7625 | W12: 41.8886 | X12: 41.988 | Y12: 41.5625 | Z12: 0.0509 | AA12: 0.0008 | AB12: 0.005 | AC12: 0.0048 | AD12: 0.0006 | AE12: 0.0042 | AF12: 41.7422 | AG12: 6.1368 | AH12: 0 | AI12: 44.883 | AJ12: 0.065 | AK12: 0.002 | AL12: =IF(F12=1,V12,AL11) -> 44.162
A13: =A12+1 -> 11 | B13: 1 | C13: 25 | D13: 0.005 | E13: 1 | F13: 10 | G13: 3 | H13: 0.0333 | I13: 30 | J13: 30 | K13: 41.7203 | L13: 41.8131 | M13: 41.5855 | N13: 71.594 | O13: 0.0882 | P13: 0 | Q13: 0.0033 | R13: 0.0022 | S13: 0.0055 | T13: 0.053188261 | V13: 41.8131 | W13: 41.8658 | X13: 42.0048 | Y13: 41.5855 | Z13: 0.0882 | AA13: 0.0048 | AB13: 0.0043 | AC13: 0.0055 | AD13: 0.0022 | AE13: 0.0033 | AF13: 41.7203 | AG13: 71.594 | AH13: 0 | AI13: 44.918 | AJ13: 0.1445 | AK13: 0.011 | AL13: =IF(F13=1,V13,AL12) -> 44.162
A14: =A13+1 -> 12 | B14: 1 | C14: 25 | D14: 0.005 | E14: 1 | F14: 10 | G14: 3 | H14: 0.0333 | I14: 30 | J14: 20 | K14: 41.7205 | L14: 41.8151 | M14: 41.6163 | N14: 109.7267 | O14: 0.2301 | P14: 0 | Q14: 0.0025 | R14: 0.0023 | S14: 0.0048 | T14: 0.053142974 | V14: 41.8151 | W14: 41.8697 | X14: 42.2584 | Y14: 41.6163 | Z14: 0.2301 | AA14: 0.0088 | AB14: 0.0159 | AC14: 0.0048 | AD14: 0.0023 | AE14: 0.0025 | AF14: 41.7205 | AG14: 109.7267 | AH14: 0 | AI14: 45.0175 | AJ14: 0.3833 | AK14: 0.0159 | AL14: =IF(F14=1,V14,AL13) -> 44.162
... A71: =A70+1 -> 69 | B71: 1 | C71: 200 | D71: 0.005 | E71: 1 | F71: 10 | G71: 3 | H71: 0.0333 | I71: 30 | J71: 20 | K71: 346.2182 | L71: 324.2057 | M71: 321.1523 | N71: 3600.5023 | O71: 1.8914 | P71: 0.0727 | Q71: 0.077 | R71: -0.0629 | S71: 0.0095 | T71: 0.079627826 | V71: 324.2057 | W71: 324.2057 | X71: 329.848 | Y71: 321.1523 | Z71: 1.8914 | AA71: 0.1407 | AB71: 0.2212 | AC71: 0.0095 | AD71: -0.0629 | AE71: 0.077 | AF71: 346.2182 | AG71: 3600.5023 | AH71: 0.0727 | AI71: 339.5965 | AJ71: 2.0371 | AK71: 0.145 | AL71: =IF(F71=1,V71,AL70) -> 352.255
A72: =A71+1 -> 70 | B72: 1 | C72: 200 | D72: 0.005 | E72: 1 | F72: 10 | G72: 3 | H72: 0.0333 | I72: 30 | J72: 10 | K72: nan | L72: 323.902 | M72: 321.0865 | N72: nan | O72: 7.8204 | P72: nan | Q72: nan | R72: nan | S72: 0.0088 | T72: 0.080489986 | V72: 323.902 | W72: 323.917 | X72: 330.8978 | Y72: 321.0865 | Z72: 7.8204 | AA72: 0.3624 | AB72: 0.4565 | AC72: 0.0088 | AD72: nan | AE72: nan | AF72: nan | AG72: nan | AH72: nan | AI72: 339.4845 | AJ72: 8.9098 | AK72: 0.4296 | AL72: =IF(F72=1,V72,AL71) -> 352.255
A73: =A72+1 -> 71 | B73: 1 | C73: 200 | D73: 0.005 | E73: 1 | F73: 10 | G73: 2 | H73: 0.0333 | I73: 30 | J73: 50 | K73: 329.8357 | L73: 322.3838 | M73: 321.18 | N73: 3599.0584 | O73: 0.57 | P73: 0.0272 | Q73: 0.027 | R73: -0.0227 | S73: 0.0037 | T73: 0.084799932 | V73: 322.3838 | W73: 323.5917 | X73: 326.7325 | Y73: 321.18 | Z73: 0.57 | AA73: 0.0455 | AB73: 0.0714 | AC73: 0.0037 | AD73: -0.0227 | AE73: 0.027 | AF73: 329.8357 | AG73: 3599.0584 | AH73: 0.0272 | AI73: 339.6545 | AJ73: 0.7221 | AK73: 0.096 | AL73: =IF(F73=1,V73,AL72) -> 352.255
A74: =A73+1 -> 72 | B74: 1 | C74: 200 | D74: 0.005 | E74: 1 | F74: 10 | G74: 1 | H74: 0.0333 | I74: 30 | J74: 50 | K74: 343.9041 | L74: 322.3138 | M74: 321.0867 | N74: 3600.2749 | O74: 0.5857 | P74: 0.0671 | Q74: 0.0711 | R74: -0.0627 | S74: 0.0039 | T74: 0.084998652 | V74: 322.3138 | W74: 323.6516 | X74: 327.0566 | Y74: 321.0867 | Z74: 0.5857 | AA74: 0.0195 | AB74: 0.0733 | AC74: 0.0039 | AD74: -0.0627 | AE74: 0.0711 | AF74: 343.9041 | AG74: 3600.2749 | AH74: 0.0671 | AI74: 339.535 | AJ74: 0.733 | AK74: 0.0492 | AL74: =IF(F74=1,V74,AL73) -> 352.255
A75: =A74+1 -> 73 | B75: 1 | C75: 200 | D75: 0.005 | E75: 1 | F75: 10 | G75: 3 | H75: 0.0333 | I75: 60 | J75: 50 | K75: 325.6008 | L75: 321.0209 | M75: 320.7097 | N75: 3604.3633 | O75: 0.3304 | P75: 0.0156 | Q75: 0.0154 | R75: -0.0142 | S75: 0.001 | T75: 0.088669004 | V75: 321.0209 | W75: 321.1734 | X75: 322.3374 | Y75: 320.7097 | Z75: 0.3304 | AA75: 0.0194 | AB75: 0.0415 | AC75: 0.001 | AD75: -0.0142 | AE75: 0.0154 | AF75: 325.6008 | AG75: 3604.3633 | AH75: 0.0156 | AI75: 339.1045 | AJ75: 0.4163 | AK75: 0.0321 | AL75: =IF(F75=1,V75,AL74) -> 352.255
A76: =A75+1 -> 74 | B76: 1 | C76: 200 | D76: 0.005 | E76: 1 | F76: 10 | G76: 3 | H76: 0.0333 | I76: 90 | J76: 50 | K76: 327.6976 | L76: 320.6977 | M76: 320.6334 | N76: 3612.531 | O76: 0.286 | P76: 0.0219 | Q76: 0.0221 | R76: -0.0214 | S76: 0.0002 | T76: 0.089586521 | V76: 320.6977 | W76: 320.7276 | X76: 321.1615 | Y76: 320.6334 | Z76: 0.286 | AA76: 0.0169 | AB76: 0.0475 | AC76: 0.0002 | AD76: -0.0214 | AE76: 0.0221 | AF76: 327.6976 | AG76: 3612.531 | AH76: 0.0219 | AI76: 339.079 | AJ76: 0.4299 | AK76: 0.031 | AL76: =IF(F76=1,V76,AL75) -> 352.255
A77: =A76+1 -> 75 | B77: 1 | C77: 200 | D77: 0.005 | E77: 1 | F77: 10 | G77: 3 | H77: 0.0333 | I77: 120 | J77: 50 | K77: 326.6596 | L77: 320.6255 | M77: 320.6255 | N77: 3603.3086 | O77: 0.3268 | P77: 0.0188 | Q77: 0.0189 | R77: -0.0185 | S77: 0 | T77: 0.089791486 | V77: 320.6255 | W77: 320.655 | X77: 320.636 | Y77: 320.6255 | Z77: 0.3268 | AA77: 0.0096 | AB77: 0.0316 | AC77: 0 | AD77: -0.0185 | AE77: 0.0189 | AF77: 326.6596 | AG77: 3603.3086 | AH77: 0.0188 | AI77: 339.079 | AJ77: 0.3639 | AK77: 0.0163 | AL77: =IF(F77=1,V77,AL76) -> 352.255
A78: =A77+1 -> 76 | B78: 1 | C78: 500 | D78: 0.005 | E78: 1 | F78: 1 | G78: 3 | H78: 0.0333 | I78: 30 | J78: 50 | K78: nan | L78: 879.684 | M78: 879.684 | N78: nan | O78: 1.725 | P78: nan | Q78: 0 | S78: 0.0355 | T78: 0 | V78: 879.684 | W78: 879.684 | X78: 879.684 | Y78: 879.684 | Z78: 1.725 | AA78: 0.0355 | AB78: 0.1311 | AC78: 0 | AD78: nan | AE78: nan | AF78: nan | AG78: nan | AH78: nan | AI78: 915.985 | AJ78: 1.8797 | AK78: 0.0967 | AL78: =IF(F78=1,V78,AL77) -> 879.684
A79: =A78+1 -> 77 | B79: 1 | C79: 500 | D79: 0.005 | E79: 1 | F79: 2 | G79: 3 | H79: 0.0333 | I79: 30 | J79: 50 | K79: nan | L79: 835.741 | M79: 835.741 | N79: nan | O79: 1.0322 | P79: nan | Q79: 0 | R79: 0.0057 | S79: 0.0857 | T79: 0.049953165 | V79: 835.741 | W79: 835.7957 | X79: 835.741 | Y79: 835.741 | Z79: 1.0322 | AA79: 0.0857 | AB79: 0.115 | AC79: 0 | AD79: nan | AE79: nan | AF79: nan | AG79: nan | AH79: nan | AI79: 870.2445 | AJ79: 1.3502 | AK79: 0.1748 | AL79: =IF(F79=1,V79,AL78) -> 879.684
A80: =A79+1 -> 78 | B80: 1 | C80: 500 | D80: 0.005 | E80: 1 | F80: 3 | G80: 3 | H80: 0.0333 | I80: 30 | J80: 50 | K80: nan | L80: 821.2219 | M80: 821.1132 | N80: nan | O80: 0.8169 | P80: nan | Q80: 0.0001 | S80: 0.075 | T80: 0.066458069 | V80: 821.2219 | W80: 821.3628 | X80: 821.2219 | Y80: 821.1132 | Z80: 0.8169 | AA80: 0.075 | AB80: 0.0979 | AC80: 0.0001 | AD80: nan | AE80: nan | AF80: nan | AG80: nan | AH80: nan | AI80: 855.016 | AJ80: 0.9084 | AK80: 0.0805 | AL80: =IF(F80=1,V80,AL79) -> 879.684
A81: =A80+1 -> 79 | B81: 1 | C81: 500 | D81: 0.005 | E81: 1 | F81: 4 | G81: 3 | H81: 0.0333 | I81: 30 | J81: 50 | K81: nan | L81: 814.1927 | M81: 813.7831 | N81: nan | O81: 0.6466 | P81: nan | Q81: 0.0005 | S81: 0.08 | T81: 0.074448666 | V81: 814.1927 | W81: 814.4428 | X81: 814.2488 | Y81: 813.7831 | Z81: 0.6466 | AA81: 0.08 | AB81: 0.1076 | AC81: 0.0005 | AD81: nan | AE81: nan | AF81: nan | AG81: nan | AH81: nan | AI81: 847.362 | AJ81: 0.6725 | AK81: 0.0809 | AL81: =IF(F81=1,V81,AL80) -> 879.684
A82: =A81+1 -> 80 | B82: 1 | C82: 500 | D82: 0.005 | E82: 1 | F82: 5 | G82: 3 | H82: 0.0333 | I82: 30 | J82: 50 | K82: nan | L82: 810.1002 | M82: 809.3935 | N82: nan | O82: 0.7976 | P82: nan | Q82: 0.0009 | S82: 0.0867 | T82: 0.079100904 | V82: 810.1002 | W82: 810.2963 | X82: 810.8252 | Y82: 809.3935 | Z82: 0.7976 | AA82: 0.0867 | AB82: 0.1016 | AC82: 0.0009 | AD82: nan | AE82: nan | AF82: nan | AG82: nan | AH82: nan | AI82: 842.795 | AJ82: 1.0704 | AK82: 0.1599 | AL82: =IF(F82=1,V82,AL81) -> 879.684
A83: =A82+1 -> 81 | B83: 1 | C83: 500 | D83: 0.005 | E83: 1 | F83: 6 | G83: 3 | H83: 0.0333 | I83: 30 | J83: 50 | K83: nan | L83: 807.6218 | M83: 806.5096 | N83: nan | O83: 0.8343 | P83: nan | Q83: 0.0014 | R83: 0.1379 | S83: 0.0798 | T83: 0.08191828 | V83: 807.6218 | W83: 807.6732 | X83: 809.025 | Y83: 806.5096 | Z83: 0.8343 | AA83: 0.0798 | AB83: 0.1379 | AC83: 0.0014 | AD83: nan | AE83: nan | AF83: nan | AG83: nan | AH83: nan | AI83: 839.7925 | AJ83: 0.9253 | AK83: 0.0961 | AL83: =IF(F83=1,V83,AL82) -> 879.684
A84: =A83+1 -> 82 | B84: 1 | C84: 500 | D84: 0.005 | E84: 1 | F84: 7 | G84: 3 | H84: 0.0333 | I84: 30 | J84: 50 | K84: nan | L84: 805.3485 | M84: 804.452 | N84: nan | O84: 1.0399 | P84: nan | Q84: 0.0011 | R84: 0.1519 | S84: 0.0671 | T84: 0.084502503 | V84: 805.3485 | W84: 805.984 | X84: 807.5701 | Y84: 804.452 | Z84: 1.0399 | AA84: 0.0671 | AB84: 0.1519 | AC84: 0.0011 | AD84: nan | AE84: nan | AF84: nan | AG84: nan | AH84: nan | AI84: 837.658 | AJ84: 1.2496 | AK84: 0.0971 | AL84: =IF(F84=1,V84,AL83) -> 879.684
A85: =A84+1 -> 83 | B85: 1 | C85: 500 | D85: 0.005 | E85: 1 | F85: 8 | G85: 3 | H85: 0.0333 | I85: 30 | J85: 50 | K85: nan | L85: 804.5435 | M85: 802.8827 | N85: nan | O85: 0.8585 | P85: nan | Q85: 0.0021 | R85: 0.1745 | S85: 0.0959 | T85: 0.085417605 | V85: 804.5435 | W85: 804.5823 | X85: 807.4382 | Y85: 802.8827 | Z85: 0.8585 | AA85: 0.0959 | AB85: 0.1745 | AC85: 0.0021 | AD85: nan | AE85: nan | AF85: nan | AG85: nan | AH85: nan | AI85: 835.985 | AJ85: 1.052 | AK85: 0.1041 | AL85: =IF(F85=1,V85,AL84) -> 879.684
A86: =A85+1 -> 84 | B86: 1 | C86: 500 | D86: 0.005 | E86: 1 | F86: 9 | G86: 3 | H86: 0.0333 | I86: 30 | J86: 50 | K86: nan | L86: 803.2052 | M86: 801.7078 | N86: nan | O86: 0.9111 | P86: nan | Q86: 0.0019 | R86: 0.1953 | S86: 0.093 | T86: 0.086938946 | V86: 803.2052 | W86: 803.4742 | X86: 807.072 | Y86: 801.7078 | Z86: 0.9111 | AA86: 0.093 | AB86: 0.1953 | AC86: 0.0019 | AD86: nan | AE86: nan | AF86: nan | AG86: nan | AH86: nan | AI86: 834.7495 | AJ86: 1.2249 | AK86: 0.1251 | AL86: =IF(F86=1,V86,AL85) -> 879.684
A87: =A86+1 -> 85 | B87: 1 | C87: 500 | D87: 0.005 | E87: 1 | F87: 10 | G87: 3 | H87: 0.0333 | I87: 30 | J87: 50 | K87: nan | L87: 802.1015 | M87: 800.7706 | N87: nan | O87: 1.2015 | P87: nan | Q87: 0.0017 | R87: 0.2251 | S87: 0.0848 | T87: 0.088193601 | V87: 802.1015 | W87: 802.8039 | X87: 806.5437 | Y87: 800.7706 | Z87: 1.2015 | AA87: 0.0848 | AB87: 0.2251 | AC87: 0.0017 | AD87: nan | AE87: nan | AF87: nan | AG87: nan | AH87: nan | AI87: 833.828 | AJ87: 1.4909 | AK87: 0.1111 | AL87: =IF(F87=1,V87,AL86) -> 879.684
A88: =A87+1 -> 86 | B88: 1 | C88: 500 | D88: 0.005 | E88: 1 | F88: 10 | G88: 3 | H88: 0.0333 | I88: 30 | J88: 40 | K88: nan | L88: 802.0619 | M88: 800.715 | N88: nan | O88: 1.6284 | P88: nan | Q88: 0.0017 | R88: 0.2711 | S88: 0.104 | T88: 0.088238618 | V88: 802.0619 | W88: 802.728 | X88: 807.9172 | Y88: 800.715 | Z88: 1.6284 | AA88: 0.104 | AB88: 0.2711 | AC88: 0.0017 | AD88: nan | AE88: nan | AF88: nan | AG88: nan | AH88: nan | AI88: 833.758 | AJ88: 2.2664 | AK88: 0.1325 | AL88: =IF(F88=1,V88,AL87) -> 879.684
A89: =A88+1 -> 87 | B89: 1 | C89: 500 | D89: 0.005 | E89: 1 | F89: 10 | G89: 3 | H89: 0.0333 | I89: 30 | J89: 30 | K89: nan | L89: 803.0232 | M89: 800.7667 | N89: nan | O89: 2.3226 | P89: nan | Q89: 0.0028 | R89: 0.424 | S89: 0.1941 | T89: 0.087145839 | V89: 803.0232 | W89: 803.0918 | X89: 810.4598 | Y89: 800.7667 | Z89: 2.3226 | AA89: 0.1941 | AB89: 0.424 | AC89: 0.0028 | AD89: nan | AE89: nan | AF89: nan | AG89: nan | AH89: nan | AI89: 833.8205 | AJ89: 2.5901 | AK89: 0.2066 | AL89: =IF(F89=1,V89,AL88) -> 879.684
A90: =A89+1 -> 88 | B90: 1 | C90: 500 | D90: 0.005 | E90: 1 | F90: 10 | G90: 3 | H90: 0.0333 | I90: 30 | J90: 20 | K90: nan | L90: 803.4025 | M90: 800.7581 | N90: nan | O90: 5.5132 | P90: nan | Q90: 0.0033 | R90: 0.9448 | S90: 0.3632 | T90: 0.086714661 | V90: 803.4025 | W90: 803.5648 | X90: 817.1922 | Y90: 800.7581 | Z90: 5.5132 | AA90: 0.3632 | AB90: 0.9448 | AC90: 0.0033 | AD90: nan | AE90: nan | AF90: nan | AG90: nan | AH90: nan | AI90: 833.7875 | AJ90: 6.169 | AK90: 0.4407 | AL90: =IF(F90=1,V90,AL89) -> 879.684
A91: =A90+1 -> 89 | B91: 1 | C91: 500 | D91: 0.005 | E91: 1 | F91: 10 | G91: 3 | H91: 0.0333 | I91: 30 | J91: 10 | K91: nan | L91: 802.9555 | M91: 800.751 | N91: nan | O91: 20.3148 | P91: nan | Q91: 0.0028 | R91: 1.93 | S91: 0.7519 | T91: 0.087222798 | V91: 802.9555 | W91: 803.0236 | X91: 821.6726 | Y91: 800.751 | Z91: 20.3148 | AA91: 0.7519 | AB91: 1.93 | AC91: 0.0028 | AD91: nan | AE91: nan | AF91: nan | AG91: nan | AH91: nan | AI91: 833.8015 | AJ91: 22.2771 | AK91: 0.9222 | AL91: =IF(F91=1,V91,AL90) -> 879.684
A92: =A91+1 -> 90 | B92: 1 | C92: 500 | D92: 0.005 | E92: 1 | F92: 10 | G92: 2 | H92: 0.0333 | I92: 30 | J92: 50 | K92: nan | L92: 802.3586 | M92: 800.7501 | N92: nan | O92: 1.318 | P92: nan | Q92: 0.002 | R92: 0.2617 | S92: 0.0881 | T92: 0.087901337 | V92: 802.3586 | W92: 803.2561 | X92: 810.0858 | Y92: 800.7501 | Z92: 1.318 | AA92: 0.0881 | AB92: 0.2617 | AC92: 0.002 | AD92: nan | AE92: nan | AF92: nan | AG92: nan | AH92: nan | AI92: 833.7845 | AJ92: 1.5645 | AK92: 0.1297 | AL92: =IF(F92=1,V92,AL91) -> 879.684
A93: =A92+1 -> 91 | B93: 1 | C93: 500 | D93: 0.005 | E93: 1 | F93: 10 | G93: 1 | H93: 0.0333 | I93: 30 | J93: 50 | K93: nan | L93: 801.9573 | M93: 800.7335 | N93: nan | O93: 1.4843 | P93: nan | Q93: 0.0015 | R93: 0.29 | S93: 0.0832 | T93: 0.088357524 | V93: 801.9573 | W93: 802.7421 | X93: 811.736 | Y93: 800.7335 | Z93: 1.4843 | AA93: 0.0832 | AB93: 0.29 | AC93: 0.0015 | AD93: nan | AE93: nan | AF93: nan | AG93: nan | AH93: nan | AI93: 833.8055 | AJ93: 1.9771 | AK93: 0.1279 | AL93: =IF(F93=1,V93,AL92) -> 879.684
A94: =A93+1 -> 92 | B94: 1 | C94: 500 | D94: 0.005 | E94: 1 | F94: 10 | G94: 3 | H94: 0.0333 | I94: 60 | J94: 50 | K94: nan | L94: 800.7682 | M94: 800.5725 | N94: nan | O94: 0.8394 | P94: nan | Q94: 0.0002 | R94: 0.0884 | S94: 0.0532 | T94: 0.089709259 | V94: 800.7682 | W94: 800.843 | X94: 801.0263 | Y94: 800.5725 | Z94: 0.8394 | AA94: 0.0532 | AB94: 0.0884 | AC94: 0.0002 | AD94: nan | AE94: nan | AF94: nan | AG94: nan | AH94: nan | AI94: 833.6395 | AJ94: 1.2415 | AK94: 0.0801 | AL94: =IF(F94=1,V94,AL93) -> 879.684
... A134: =A133+1 -> 132 | B134: 1 | C134: 2000 | D134: 0.005 | E134: 1 | F134: 10 | G134: 3 | H134: 0.0333 | I134: 120 | J134: 50 | K134: nan | L134: 3211.2535 | M134: 3211.2535 | N134: nan | O134: 7.4016 | P134: nan | Q134: 0 | R134: 0.6659 | S134: 0.1452 | T134: 0.089981175 | V134: 3211.2535 | W134: 3211.2535 | X134: 3211.2535 | Y134: 3211.2535 | Z134: 7.4016 | AA134: 0.1452 | AB134: 0.6659 | AC134: 0 | AD134: nan | AE134: nan | AF134: nan | AG134: nan | AH134: nan | AI134: 3348.719 | AJ134: 8.8425 | AK134: 0.2851 | AL134: =IF(F134=1,V134,AL133) -> 3528.777

Sheet LAA
A1: case | B1: seed | C1: nV | D1: uvl | E1: fsd | F1: N | G1: dc | H1: charging_speed | I1: dwl | J1: ad | K1: LOOK AHEAD | L1: e_forward | M1: e_backward | N1: lower_bound | O1: lower_bound_f | P1: CPU LOOK AHEAD | Q1: cpu_forward | R1: cpu_backward | S1: time.time()-start_data_time | T1: min_p_middle | U1: min_p_middle_value | V1: mean_delay_to_entry_(minute) | W1: mean_sum_waiting_platoon_(minute) | X1: mean_Saving_energy | Y1: mean_Saving_energy(%) | Z1: mean_before_due_time_(minute) | AA1: mean_duration_trip_alone_(minute) | AB1: mean_Saving_time_(minute) | AC1: mean_Saving_time(%) | AD1: std_delay_to_entry_(minute) | AE1: std_sum_waiting_platoon_(minute) | AF1: std_Saving_energy | AG1: std_Saving_energy(%) | AH1: std_before_due_time_(minute) | AI1: std_duration_trip_alone_(minute) | AJ1: std_Saving_time_(minute) | AK1: std_Saving_time(%) | AL1: min_delay_to_entry_(minute) | AM1: min_sum_waiting_platoon_(minute) | AN1: min_Saving_energy | AO1: min_Saving_energy(%) | AP1: min_before_due_time_(minute) | AQ1: min_duration_trip_alone_(minute) | AR1: min_Saving_time_(minute) | AS1: min_Saving_time(%) | AT1: max_delay_to_entry_(minute) | AU1: max_sum_waiting_platoon_(minute) | AV1: max_Saving_energy | AW1: max_Saving_energy(%) | AX1: max_before_due_time_(minute) | AY1: max_duration_trip_alone_(minute) | AZ1: max_Saving_time_(minute) | BA1: max_Saving_time(%) | BB1: max_cc_5 | BC1: mean_cc_5 | BD1: max_cc_10 | BE1: mean_cc_10 | BF1: max_cc_15 | BG1: mean_cc_15 | BH1: max_cc_20 | BI1: mean_cc_20 | BJ1: max_cc_25 | BK1: mean_cc_25 | BL1: max_cc_30 | BM1: mean_cc_30 | BN1: Column16 | BO1: Column17 | BP1: platoon_size_1 | BQ1: platoon_size_2 | BR1: platoon_size_3 | BS1: platoon_size_4 | BT1: platoon_size_5 | BU1: platoon_size_6 | BV1: platoon_size_7 | BW1: platoon_size_8 | BX1: platoon_size_9 | BY1: platoon_size_10
A2: 0 | B2: 1 | C2: 25 | D2: 0.005 | E2: 1 | F2: 1 | G2: 3 | H2: 0.0333 | I2: 30 | J2: 50 | K2: 42.455 | L2: 42.455 | M2: 42.455 | N2: 42.455 | O2: 42.455 | P2: 0.0038464069 | Q2: 0.0038464069 | R2: 0.0038464069 | S2: 0.77141857 | T2: 'p0' | U2: '42.45500000000001' | V2: 0 | W2: 0 | X2: 0 | Y2: 0 | Z2: 0 | AA2: 294.26754 | AB2: 0 | AC2: 0 | AD2: 0 | AE2: 0 | AF2: 0 | AG2: 0 | AH2: 0 | AI2: 94.119082 | AJ2: 0 | AK2: 0 | AL2: 0 | AM2: 0 | AN2: 0 | AO2: 0 | AP2: 0 | AQ2: 149.71096 | AR2: 0 | AS2: 0 | AT2: 0 | AU2: 0 | AV2: 0 | AW2: 0 | AX2: 0 | AY2: 435.66066 | AZ2: 0 | BA2: 0 | BB2: 4 | BC2: 1 | BD2: 4 | BE2: 2 | BF2: 4 | BG2: 2 | BH2: 4 | BI2: 2 | BJ2: 4 | BK2: 2 | BL2: 5 | BM2: 2 | BN2: 'Run_all_with_output' | BO2: ''] | BP2: 1 | BQ2: 0 | BR2: 0 | BS2: 0 | BT2: 0 | BU2: 0 | BV2: 0 | BW2: 0 | BX2: 0 | BY2: 0
A3: 1 | B3: 1 | C3: 25 | D3: 0.005 | E3: 1 | F3: 2 | G3: 3 | H3: 0.0333 | I3: 30 | J3: 50 | K3: 40.8475 | L3: 40.878 | M3: 40.9245 | N3: 40.858 | O3: 40.6215 | P3: 0.13871861 | Q3: 0 | R3: 0.0090222359 | S3: 1.0627172 | T3: 'p5' | U3: '40.8475' | V3: 8.3248467 | W3: 0.12012012 | X3: 0.0651 | Y3: 3.7476442 | Z3: 0 | AA3: 294.26754 | AB3: 1.954955 | AC3: 0.6513804 | AD3: 11.12275 | AE3: 0.41574694 | AF3: 0.050797187 | AG3: 2.7259724 | AH3: 0 | AI3: 94.119082 | AJ3: 1.525441 | AK3: 0.47732862 | AL3: -2.842171e-14 | AM3: 0 | AN3: 0 | AO3: 0 | AP3: 0 | AQ3: 149.71096 | AR3: 0 | AS3: 0 | AT3: 39.77649 | AU3: 1.5015015 | AV3: 0.1575 | AW3: 10 | AX3: 0 | AY3: 435.66066 | AZ3: 4.7297297 | BA3: 1.805281 | BB3: 4 | BC3: 1 | BD3: 5 | BE3: 2 | BF3: 4 | BG3: 2 | BH3: 5 | BI3: 2 | BJ3: 5 | BK3: 2 | BL3: 5 | BM3: 2 | BN3: 'Run_all_with_output' | BO3: ''] | BP3: 0.22807018 | BQ3: 0.77192982 | BR3: 0 | BS3: 0 | BT3: 0 | BU3: 0 | BV3: 0 | BW3: 0 | BX3: 0 | BY3: 0
A4: 2 | B4: 1 | C4: 25 | D4: 0.005 | E4: 1 | F4: 3 | G4: 3 | H4: 0.0333 | I4: 30 | J4: 50 | K4: 40.469 | L4: 40.4995 | M4: 40.6585 | N4: 40.4995 | O4: 40.2885 | P4: 0.20905256 | Q4: 0.0030055046 | R4: 0.016045809 | S4: 1.1197882 | T4: 'p5' | U4: '40.469' | V4: 8.6984281 | W4: 0.12012012 | X4: 0.07944 | Y4: 4.5108196 | Z4: 0 | AA4: 294.26754 | AB4: 2.3855856 | AC4: 0.78027822 | AD4: 11.837472 | AE4: 0.41574694 | AF4: 0.064663282 | AG4: 3.1313859 | AH4: 0 | AI4: 94.119082 | AJ4: 1.9418403 | AK4: 0.54538331 | AL4: -5.684342e-14 | AM4: 0 | AN4: 0 | AO4: 0 | AP4: 0 | AQ4: 149.71096 | AR4: 0 | AS4: 0 | AT4: 39.77649 | AU4: 1.5015015 | AV4: 0.2075 | AW4: 10 | AX4: 0 | AY4: 435.66066 | AZ4: 6.2312312 | BA4: 1.805281 | BB4: 4 | BC4: 1 | BD4: 5 | BE4: 2 | BF4: 4 | BG4: 2 | BH4: 5 | BI4: 2 | BJ4: 5 | BK4: 2 | BL4: 5 | BM4: 2 | BN4: 'Run_all_with_output' | BO4: ''] | BP4: 0.21637427 | BQ4: 0.32748538 | BR4: 0.45614035 | BS4: 0 | BT4: 0 | BU4: 0 | BV4: 0 | BW4: 0 | BX4: 0 | BY4: 0
A5: 3 | B5: 1 | C5: 25 | D5: 0.005 | E5: 1 | F5: 4 | G5: 3 | H5: 0.0333 | I5: 30 | J5: 50 | K5: 40.199 | L5: 40.26 | M5: 40.411 | N5: 40.26 | O5: 40.153 | P5: 0.16676259 | Q5: 0.0020313263 | R5: 0.0095584393 | S5: 1.1279609 | T5: 'p5' | U5: '40.199' | V5: 11.08294 | W5: 0.13753754 | X5: 0.09024 | Y5: 5.1365289 | Z5: 0 | AA5: 294.26754 | AB5: 2.7099099 | AC5: 0.88789213 | AD5: 13.84554 | AE5: 0.41960811 | AF5: 0.06636156 | AG5: 3.0875056 | AH5: 0 | AI5: 94.119082 | AJ5: 1.9928396 | AK5: 0.53483839 | AL5: -5.684342e-14 | AM5: 0 | AN5: 0 | AO5: 0 | AP5: 0 | AQ5: 149.71096 | AR5: 0 | AS5: 0 | AT5: 45.501677 | AU5: 1.5015015 | AV5: 0.2075 | AW5: 10 | AX5: 0 | AY5: 435.66066 | AZ5: 6.2312312 | BA5: 1.805281 | BB5: 4 | BC5: 1 | BD5: 5 | BE5: 2 | BF5: 4 | BG5: 2 | BH5: 5 | BI5: 2 | BJ5: 5 | BK5: 2 | BL5: 5 | BM5: 2 | BN5: 'Run_all_with_output' | BO5: ''] | BP5: 0.15204678 | BQ5: 0.32748538 | BR5: 0.26315789 | BS5: 0.25730994 | BT5: 0 | BU5: 0 | BV5: 0 | BW5: 0 | BX5: 0 | BY5: 0
A6: 4 | B6: 1 | C6: 25 | D6: 0.005 | E6: 1 | F6: 5 | G6: 3 | H6: 0.0333 | I6: 30 | J6: 50 | K6: 40.199 | L6: 40.26 | M6: 40.411 | N6: 40.26 | O6: 40.153 | P6: 0.10449004 | Q6: 0.002007246 | R6: 0 | S6: 1.0319226 | T6: 'p5' | U6: '40.199' | V6: 11.08294 | W6: 0.13753754 | X6: 0.09024 | Y6: 5.1365289 | Z6: 0 | AA6: 294.26754 | AB6: 2.7099099 | AC6: 0.88789213 | AD6: 13.84554 | AE6: 0.41960811 | AF6: 0.06636156 | AG6: 3.0875056 | AH6: 0 | AI6: 94.119082 | AJ6: 1.9928396 | AK6: 0.53483839 | AL6: -5.684342e-14 | AM6: 0 | AN6: 0 | AO6: 0 | AP6: 0 | AQ6: 149.71096 | AR6: 0 | AS6: 0 | AT6: 45.501677 | AU6: 1.5015015 | AV6: 0.2075 | AW6: 10 | AX6: 0 | AY6: 435.66066 | AZ6: 6.2312312 | BA6: 1.805281 | BB6: 4 | BC6: 1 | BD6: 5 | BE6: 2 | BF6: 4 | BG6: 2 | BH6: 5 | BI6: 2 | BJ6: 5 | BK6: 2 | BL6: 5 | BM6: 2 | BN6: 'Run_all_with_output' | BO6: ''] | BP6: 0.15204678 | BQ6: 0.32748538 | BR6: 0.26315789 | BS6: 0.25730994 | BT6: 0 | BU6: 0 | BV6: 0 | BW6: 0 | BX6: 0 | BY6: 0
A7: 5 | B7: 1 | C7: 25 | D7: 0.005 | E7: 1 | F7: 6 | G7: 3 | H7: 0.0333 | I7: 30 | J7: 50 | K7: 40.199 | L7: 40.26 | M7: 40.411 | N7: 40.26 | O7: 40.153 | P7: 0.24077296 | Q7: 0 | R7: 0.0051939487 | S7: 1.1114986 | T7: 'p5' | U7: '40.199' | V7: 11.08294 | W7: 0.13753754 | X7: 0.09024 | Y7: 5.1365289 | Z7: 0 | AA7: 294.26754 | AB7: 2.7099099 | AC7: 0.88789213 | AD7: 13.84554 | AE7: 0.41960811 | AF7: 0.06636156 | AG7: 3.0875056 | AH7: 0 | AI7: 94.119082 | AJ7: 1.9928396 | AK7: 0.53483839 | AL7: -5.684342e-14 | AM7: 0 | AN7: 0 | AO7: 0 | AP7: 0 | AQ7: 149.71096 | AR7: 0 | AS7: 0 | AT7: 45.501677 | AU7: 1.5015015 | AV7: 0.2075 | AW7: 10 | AX7: 0 | AY7: 435.66066 | AZ7: 6.2312312 | BA7: 1.805281 | BB7: 4 | BC7: 1 | BD7: 5 | BE7: 2 | BF7: 4 | BG7: 2 | BH7: 5 | BI7: 2 | BJ7: 5 | BK7: 2 | BL7: 5 | BM7: 2 | BN7: 'Run_all_with_output' | BO7: ''] | BP7: 0.15204678 | BQ7: 0.32748538 | BR7: 0.26315789 | BS7: 0.25730994 | BT7: 0 | BU7: 0 | BV7: 0 | BW7: 0 | BX7: 0 | BY7: 0
A8: 6 | B8: 1 | C8: 25 | D8: 0.005 | E8: 1 | F8: 7 | G8: 3 | H8: 0.0333 | I8: 30 | J8: 50 | K8: 40.199 | L8: 40.26 | M8: 40.411 | N8: 40.26 | O8: 40.153 | P8: 0.17099285 | Q8: 0.0020041466 | R8: 0.007942915 | S8: 1.0396876 | T8: 'p5' | U8: '40.199' | V8: 11.08294 | W8: 0.13753754 | X8: 0.09024 | Y8: 5.1365289 | Z8: 0 | AA8: 294.26754 | AB8: 2.7099099 | AC8: 0.88789213 | AD8: 13.84554 | AE8: 0.41960811 | AF8: 0.06636156 | AG8: 3.0875056 | AH8: 0 | AI8: 94.119082 | AJ8: 1.9928396 | AK8: 0.53483839 | AL8: -5.684342e-14 | AM8: 0 | AN8: 0 | AO8: 0 | AP8: 0 | AQ8: 149.71096 | AR8: 0 | AS8: 0 | AT8: 45.501677 | AU8: 1.5015015 | AV8: 0.2075 | AW8: 10 | AX8: 0 | AY8: 435.66066 | AZ8: 6.2312312 | BA8: 1.805281 | BB8: 4 | BC8: 1 | BD8: 5 | BE8: 2 | BF8: 4 | BG8: 2 | BH8: 5 | BI8: 2 | BJ8: 5 | BK8: 2 | BL8: 5 | BM8: 2 | BN8: 'Run_all_with_output' | BO8: ''] | BP8: 0.15204678 | BQ8: 0.32748538 | BR8: 0.26315789 | BS8: 0.25730994 | BT8: 0 | BU8: 0 | BV8: 0 | BW8: 0 | BX8: 0 | BY8: 0
A9: 7 | B9: 1 | C9: 25 | D9: 0.005 | E9: 1 | F9: 8 | G9: 3 | H9: 0.0333 | I9: 30 | J9: 50 | K9: 40.199 | L9: 40.26 | M9: 40.411 | N9: 40.26 | O9: 40.153 | P9: 0.18987894 | Q9: 0 | R9: 0.0094058514 | S9: 1.2222161 | T9: 'p5' | U9: '40.199' | V9: 11.08294 | W9: 0.13753754 | X9: 0.09024 | Y9: 5.1365289 | Z9: 0 | AA9: 294.26754 | AB9: 2.7099099 | AC9: 0.88789213 | AD9: 13.84554 | AE9: 0.41960811 | AF9: 0.06636156 | AG9: 3.0875056 | AH9: 0 | AI9: 94.119082 | AJ9: 1.9928396 | AK9: 0.53483839 | AL9: -5.684342e-14 | AM9: 0 | AN9: 0 | AO9: 0 | AP9: 0 | AQ9: 149.71096 | AR9: 0 | AS9: 0 | AT9: 45.501677 | AU9: 1.5015015 | AV9: 0.2075 | AW9: 10 | AX9: 0 | AY9: 435.66066 | AZ9: 6.2312312 | BA9: 1.805281 | BB9: 4 | BC9: 1 | BD9: 5 | BE9: 2 | BF9: 4 | BG9: 2 | BH9: 5 | BI9: 2 | BJ9: 5 | BK9: 2 | BL9: 5 | BM9: 2 | BN9: 'Run_all_with_output' | BO9: ''] | BP9: 0.15204678 | BQ9: 0.32748538 | BR9: 0.26315789 | BS9: 0.25730994 | BT9: 0 | BU9: 0 | BV9: 0 | BW9: 0 | BX9: 0 | BY9: 0
A10: 8 | B10: 1 | C10: 25 | D10: 0.005 | E10: 1 | F10: 9 | G10: 3 | H10: 0.0333 | I10: 30 | J10: 50 | K10: 40.199 | L10: 40.26 | M10: 40.411 | N10: 40.26 | O10: 40.153 | P10: 0.11633158 | Q10: 0.0020039082 | R10: 0.011804581 | S10: 1.0206053 | T10: 'p5' | U10: '40.199' | V10: 11.08294 | W10: 0.13753754 | X10: 0.09024 | Y10: 5.1365289 | Z10: 0 | AA10: 294.26754 | AB10: 2.7099099 | AC10: 0.88789213 | AD10: 13.84554 | AE10: 0.41960811 | AF10: 0.06636156 | AG10: 3.0875056 | AH10: 0 | AI10: 94.119082 | AJ10: 1.9928396 | AK10: 0.53483839 | AL10: -5.684342e-14 | AM10: 0 | AN10: 0 | AO10: 0 | AP10: 0 | AQ10: 149.71096 | AR10: 0 | AS10: 0 | AT10: 45.501677 | AU10: 1.5015015 | AV10: 0.2075 | AW10: 10 | AX10: 0 | AY10: 435.66066 | AZ10: 6.2312312 | BA10: 1.805281 | BB10: 4 | BC10: 1 | BD10: 5 | BE10: 2 | BF10: 4 | BG10: 2 | BH10: 5 | BI10: 2 | BJ10: 5 | BK10: 2 | BL10: 5 | BM10: 2 | BN10: 'Run_all_with_output' | BO10: ''] | BP10: 0.15204678 | BQ10: 0.32748538 | BR10: 0.26315789 | BS10: 0.25730994 | BT10: 0 | BU10: 0 | BV10: 0 | BW10: 0 | BX10: 0 | BY10: 0
A11: 9 | B11: 1 | C11: 25 | D11: 0.005 | E11: 1 | F11: 10 | G11: 3 | H11: 0.0333 | I11: 30 | J11: 50 | K11: 40.199 | L11: 40.26 | M11: 40.411 | N11: 40.26 | O11: 40.153 | P11: 0.23114824 | Q11: 0 | R11: 0.016341448 | S11: 1.1234131 | T11: 'p5' | U11: '40.199' | V11: 11.08294 | W11: 0.13753754 | X11: 0.09024 | Y11: 5.1365289 | Z11: 0 | AA11: 294.26754 | AB11: 2.7099099 | AC11: 0.88789213 | AD11: 13.84554 | AE11: 0.41960811 | AF11: 0.06636156 | AG11: 3.0875056 | AH11: 0 | AI11: 94.119082 | AJ11: 1.9928396 | AK11: 0.53483839 | AL11: -5.684342e-14 | AM11: 0 | AN11: 0 | AO11: 0 | AP11: 0 | AQ11: 149.71096 | AR11: 0 | AS11: 0 | AT11: 45.501677 | AU11: 1.5015015 | AV11: 0.2075 | AW11: 10 | AX11: 0 | AY11: 435.66066 | AZ11: 6.2312312 | BA11: 1.805281 | BB11: 4 | BC11: 1 | BD11: 5 | BE11: 2 | BF11: 4 | BG11: 2 | BH11: 5 | BI11: 2 | BJ11: 5 | BK11: 2 | BL11: 5 | BM11: 2 | BN11: 'Run_all_with_output' | BO11: ''] | BP11: 0.15204678 | BQ11: 0.32748538 | BR11: 0.26315789 | BS11: 0.25730994 | BT11: 0 | BU11: 0 | BV11: 0 | BW11: 0 | BX11: 0 | BY11: 0
A12: 10 | B12: 1 | C12: 25 | D12: 0.005 | E12: 1 | F12: 10 | G12: 3 | H12: 0.0333 | I12: 30 | J12: 40 | K12: 40.2215 | L12: 40.2215 | M12: 40.2915 | N12: 40.2015 | O12: 40.153 | P12: 0.20057607 | Q12: 0.0010018349 | R12: 0.010929585 | S12: 1.2412052 | T12: 'p0' | U12: '40.2215' | V12: 29.373326 | W12: 110.50848 | X12: 0.10002 | Y12: 5.6690262 | Z12: 0 | AA12: 294.3276 | AB12: 3.0036036 | AC12: 0.98377912 | AD12: 18.337705 | AE12: 72.562556 | AF12: 0.07240892 | AG12: 3.2709957 | AH12: 0 | AI12: 98.668985 | AJ12: 2.174442 | AK12: 0.56266473 | AL12: 0 | AM12: 1.5756608 | AN12: 0.02 | AO12: 1.0891089 | AP12: 0 | AQ12: 144.60586 | AR12: 0.6006006 | AS12: 0.18047728 | AT12: 74.981455 | AU12: 249.54955 | AV12: 0.23 | AW12: 10 | AX12: 0 | AY12: 442.56757 | AZ12: 6.9069069 | BA12: 1.763532 | BB12: 4 | BC12: 1 | BD12: 4 | BE12: 2 | BF12: 4 | BG12: 2 | BH12: 5 | BI12: 2 | BJ12: 4 | BK12: 2 | BL12: 5 | BM12: 2 | BN12: 'Run_all_with_output' | BO12: ''] | BP12: 0.16666667 | BQ12: 0.32323232 | BR12: 0.28787879 | BS12: 0.22222222 | BT12: 0 | BU12: 0 | BV12: 0 | BW12: 0 | BX12: 0 | BY12: 0
A13: 11 | B13: 1 | C13: 25 | D13: 0.005 | E13: 1 | F13: 10 | G13: 3 | H13: 0.0333 | I13: 30 | J13: 30 | K13: 40.2245 | L13: 40.2405 | M13: 40.422 | N13: 40.2205 | O13: 40.164 | P13: 0.40441895 | Q13: 0.0020041466 | R13: 0.014849663 | S13: 1.6444118 | T13: 'p8' | U13: '40.22449999999999' | V13: 7.521504 | W13: 0.1987988 | X13: 0.08922 | Y13: 5.016444 | Z13: 0 | AA13: 297.82309 | AB13: 2.6792793 | AC13: 0.86035383 | AD13: 10.364616 | AE13: 0.62651009 | AF13: 0.063657953 | AG13: 2.7733311 | AH13: 0 | AI13: 97.170987 | AJ13: 1.9116502 | AK13: 0.47382826 | AL13: -5.684342e-14 | AM13: 0 | AN13: 0 | AO13: 0 | AP13: 0 | AQ13: 147.90916 | AR13: 0 | AS13: 0 | AT13: 35.724855 | AU13: 2.972973 | AV13: 0.2075 | AW13: 8.3333333 | AX13: 0 | AY13: 443.16817 | AZ13: 6.2312312 | BA13: 1.4369358 | BB13: 4 | BC13: 1 | BD13: 5 | BE13: 1 | BF13: 5 | BG13: 2 | BH13: 5 | BI13: 2 | BJ13: 5 | BK13: 2 | BL13: 5 | BM13: 2 | BN13: 'Run_all_with_output' | BO13: ''] | BP13: 0.15770609 | BQ13: 0.32258065 | BR13: 0.29032258 | BS13: 0.22939068 | BT13: 0 | BU13: 0 | BV13: 0 | BW13: 0 | BX13: 0 | BY13: 0
... A666: 664 | B666: 5 | C666: 2000 | D666: 0.005 | E666: 1 | F666: 10 | G666: 3 | H666: 0.0333 | I666: 120 | J666: 50 | K666: 3348.719 | L666: 3348.719 | M666: 3348.719 | N666: 3348.719 | O666: 3348.719 | P666: 31.492463 | Q666: 0.1494081 | R666: 0.51576757 | S666: 701.15655 | T666: 'p6' | U666: '3348.7189999999737' | V666: 16.942704 | W666: 0.49493994 | X666: 0.165558 | Y666: 8.9641676 | Z666: 0 | AA666: 321.32028 | AB666: 4.9717117 | AC666: 1.540853 | AD666: 26.299712 | AE666: 1.4528984 | AF666: 0.042456627 | AG666: 1.3740617 | AH666: 0 | AI666: 62.047087 | AJ666: 1.2749738 | AK666: 0.23516006 | AL666: -5.684342e-14 | AM666: -1.1368684e-13 | AN666: 0.03 | AO666: 2.0833333 | AP666: 0 | AQ666: 177.30631 | AR666: 0.9009009 | AS666: 0.34157672 | AT666: 152.05891 | AU666: 13.198198 | AV666: 0.25 | AW666: 10 | AX666: 0 | AY666: 447.67267 | AZ666: 7.5075075 | BA666: 1.9081733 | BB666: 260 | BC666: 88 | BD666: 280 | BE666: 104 | BF666: 330 | BG666: 120 | BH666: 340 | BI666: 136 | BJ666: 390 | BK666: 152 | BL666: 390 | BM666: 170 | BN666: 'Run_all_with_output' | BO666: ''] | BP666: 7.07664e-05 | BQ666: 0 | BR666: 0 | BS666: 0 | BT666: 0.000707664 | BU666: 0.0004245984 | BV666: 0.0009907296 | BW666: 0 | BX666: 0 | BY666: 0.99780624

Sheet LAA Pivot
A1: nV | B1: 25 | D1: 25 | E1: 50 | F1: 100 | G1: 200 | H1: 500 | I1: 1000 | J1: 2000
A2: uvl | B2: 0.005 | D2: 0.005 | E2: 0.005 | F2: 0.005 | G2: 0.005 | H2: 0.005 | I2: 0.005 | J2: 0.005
A3: fsd | B3: 1 | D3: 1 | E3: 1 | F3: 1 | G3: 1 | H3: 1 | I3: 1 | J3: 1
A4: ad | B4: 50 | D4: 50 | E4: 50 | F4: 50 | G4: 50 | H4: 50 | I4: 50 | J4: 50
A5: N | B5: 10 | D5: 10 | E5: 10 | F5: 10 | G5: 10 | H5: 10 | I5: 10 | J5: 10
A6: dwl | B6: 30 | D6: 30 | E6: 30 | F6: 30 | G6: 30 | H6: 30 | I6: 30 | J6: 30
A7: charging_speed | B7: 0.0333 | D7: 0.0333 | E7: 0.0333 | F7: 0.0333 | G7: 0.0333 | H7: 0.0333 | I7: 0.0333 | J7: 0.0333
A8: dc | B8: 3 | D8: 3 | E8: 3 | F8: 3 | G8: 3 | H8: 3 | I8: 3 | J8: 3
A10: Values
A11: Average of mean_delay_to_entry_(minute) | B11: 10.59277 | D11: 10.59277 | E11: 14.270146 | F11: 13.600236 | G11: 16.231897 | H11: 14.99395 | I11: 13.836076 | J11: 12.599325
A12: Average of mean_sum_waiting_platoon_(minute) | B12: 8.9149418 | D12: 8.9149418 | E12: 9.7067937 | F12: 0.50633634 | G12: 0.40226727 | H12: 0.57619219 | I12: 2.9587868 | J12: 4.6019426
A13: Average of mean_Saving_energy | B13: 0.099928 | D13: 0.099928 | E13: 0.123324 | F13: 0.137594 | G13: 0.1517445 | H13: 0.1560902 | I13: 0.1575784 | J13: 0.15692181
A14: Average of mean_Saving_energy(%) | B14: 5.5052854 | D14: 5.5052854 | E14: 6.7547936 | F14: 7.7710971 | G14: 8.5045681 | H14: 8.8118653 | I14: 8.9129647 | J14: 8.96279
A15: Average of mean_before_due_time_(minute) | B15: -1.8567612 | D15: -1.8567612 | E15: -1.5961814 | F15: -0.99940994 | G15: 0 | H15: 0 | I15: -0.58416367 | J15: -0.80743778
A16: Average of mean_duration_trip_alone_(minute) | B16: 308.09032 | D16: 308.09032 | E16: 310.56176 | F16: 303.5705 | G16: 307.77488 | H16: 307.3637 | I16: 307.39421 | J16: 305.00935
A17: Average of mean_Saving_time_(minute) | B17: 3.0008408 | D17: 3.0008408 | E17: 3.7034234 | F17: 4.131952 | G17: 4.5568919 | H17: 4.6873934 | I17: 4.7320841 | J17: 4.7123667
A18: Average of mean_Saving_time(%) | B18: 0.94666061 | D18: 0.94666061 | E18: 1.1568405 | F18: 1.3383925 | G18: 1.4612664 | H18: 1.5144178 | I18: 1.531035 | J18: 1.5394781
A19: Average of min_duration_trip_alone_(minute) | B19: 172.33438 | D19: 172.33438 | E19: 173.41547 | F19: 171.5536 | G19: 164.58664 | H19: 163.68574 | I19: 163.05511 | J19: 158.40372
A20: Average of min_Saving_time_(minute) | B20: 0.15615616 | D20: 0.15615616 | E20: 0.26726727 | F20: 0.32132132 | G20: 0.57957958 | H20: 0.63963964 | I20: 0.48348348 | J20: 0.4954955
A21: Average of min_Saving_time(%) | B21: 0.04986953 | D21: 0.04986953 | E21: 0.085538436 | F21: 0.10270056 | G21: 0.29180288 | H21: 0.29885129 | I21: 0.22468224 | J21: 0.21869438
A22: Average of max_delay_to_entry_(minute) | B22: 48.03409 | D22: 48.03409 | E22: 55.62848 | F22: 72.745944 | G22: 97.869452 | H22: 116.08225 | I22: 134.37668 | J22: 117.56433
... A52: Average of platoon_size_10 | B52: 0 | D52: 0 | E52: 0 | F52: 0.17232284 | G52: 0.64080068 | H52: 0.86828914 | I52: 0.94693456 | J52: 0.9893129

Sheet MILP
A1: case | B1: seed | C1: nV | D1: uvl | E1: fsd | F1: N | G1: dc | H1: cs | I1: dwl | J1: ad | K1: obj MILP | L1: CPU MILP | M1: GAP MILP | N1: Gurobi Status | O1: NumVars | P1: NumConstrs | Q1: NumSOS | R1: NumQConstrs | S1: NumGenConstrs | T1: NumNZs | U1: DNumNZs | V1: NumQNZs | W1: NumQCNZs | X1: NumIntVars | Y1: NumBinVars | Z1: NumPWLObjVars | AA1: ModelName | AB1: ModelSense | AC1: ObjCon | AD1: Fingerprint | AE1: ObjVal | AF1: ObjBound | AG1: ObjBoundC | AH1: PoolObjBound | AI1: PoolObjVal | AJ1: MIP Gap | AK1: Runtime | AL1: Work | AM1: Status | AN1: SolCount | AO1: IterCount | AP1: BarIterCount | AQ1: NodeCount | AR1: OpenNodeCount | AS1: ConcurrentWinMethod | AT1: IsMIP | AU1: IsQP | AV1: IsQCP | AW1: IsMultiObj | AX1: IISMinimal | AY1: MaxCoeff | AZ1: MinCoeff | BA1: MaxBound | BB1: MinBound | BC1: MaxObjCoeff | BD1: MinObjCoeff | BE1: MaxRHS | BF1: MinRHS | BG1: MaxQCCoeff | BH1: MinQCCoeff | BI1: MaxQCRHS | BJ1: MinQCRHS | BK1: MaxQObjCoeff | BL1: MinQObjCoeff | BM1: Kappa | BN1: KappaExact | BO1: FarkasProof | BP1: TuneResultCount | BQ1: NumStart | BR1: LicenseExpiration | BS1: LB | BT1: UB | BU1: Obj | BV1: VType | BW1: VarName | BX1: VTag | BY1: X | BZ1: Xn | CA1: RC | CB1: BarX | CC1: Start | CD1: VarHintVal | CE1: VarHintPri | CF1: BranchPriority | CG1: Partition | CH1: VBasis | CI1: PStart | CJ1: IISLB | CK1: IISUB | CL1: IISLBForce | CM1: IISUBForce | CN1: PoolIgnore | CO1: PWLObjCvx | CP1: SAObjLow | CQ1: SAObjUp | CR1: SALBLow | CS1: SALBUp | CT1: SAUBLow | CU1: SAUBUp | CV1: UnbdRay | CW1: Sense | CX1: RHS | CY1: ConstrName | CZ1: CTag | DA1: Pi | DB1: Slack | DC1: CBasis | DD1: DStart | DE1: Lazy | DF1: IISConstr | DG1: IISConstrForce | DH1: SARHSLow | DI1: SARHSUp | DJ1: FarkasDual | DK1: IISSOS | DL1: IISSOSForce | DM1: QCSense | DN1: QCRHS | DO1: QCName | DP1: QCPi | DQ1: QCSlack | DR1: QCTag | DS1: IISQConstr | DT1: IISQConstrForce | DU1: FuncPieceError | DV1: FuncPieceLength | DW1: FuncPieceRatio | DX1: FuncPieces | DY1: GenConstrType | DZ1: GenConstrName | EA1: IISGenConstr | EB1: IISGenConstrForce | EC1: MaxVio | ED1: BoundVio | EE1: BoundSVio | EF1: BoundVioIndex | EG1: BoundSVioIndex | EH1: BoundVioSum | EI1: BoundSVioSum | EJ1: ConstrVio | EK1: ConstrSVio | EL1: ConstrVioIndex | EM1: ConstrSVioIndex | EN1: ConstrVioSum | EO1: ConstrSVioSum | EP1: ConstrResidual | EQ1: ConstrSResidual | ER1: ConstrResidualIndex | ES1: ConstrSResidualIndex | ET1: ConstrResidualSum | EU1: ConstrSResidualSum | EV1: DualVio | EW1: DualSVio | EX1: DualVioIndex | EY1: DualSVioIndex | EZ1: DualVioSum | FA1: DualSVioSum | FB1: DualResidual | FC1: DualSResidual | FD1: DualResidualIndex | FE1: DualSResidualIndex | FF1: DualResidualSum | FG1: DualSResidualSum | FH1: ComplVio | FI1: ComplVioIndex | FJ1: ComplVioSum | FK1: IntVio | FL1: IntVioIndex | FM1: IntVioSum | FN1: ObjN | FO1: ObjNCon | FP1: ObjNPriority | FQ1: ObjNWeight | FR1: ObjNRelTol | FS1: ObjNAbsTol | FT1: ObjNVal | FU1: ObjNName | FV1: NumObj | FW1: ScenNLB | FX1: ScenNUB | FY1: ScenNObj | FZ1: ScenNRHS | GA1: ScenNName | GB1: ScenNObjBound | GC1: ScenNObjVal | GD1: ScenNX | GE1: NumScenarios | GF1: BatchErrorCode | GG1: BatchErrorMessage | GH1: BatchID | GI1: BatchStatus | GJ1: Note
A2: 0 | B2: 1 | C2: 25 | D2: 0.005 | E2: 1 | F2: 1 | G2: 3 | H2: 0.0333 | I2: 30 | J2: 50 | K2: 42.455 | L2: 0.0091 | M2: 0 | O2: 5656 | P2: 7987 | Q2: 0 | R2: 0 | S2: 0 | T2: 15769 | U2: 15769 | V2: 0 | W2: 0 | X2: 4480 | Y2: 4480 | Z2: 0 | AA2: 'Platoon_Tree' | AB2: 1 | AC2: 0 | AD2: 1720353965 | AE2: 42.455 | AF2: 42.455 | AG2: 42.455 | AH2: 42.455 | AI2: 42.455 | AJ2: 0 | AK2: 0.017999887 | AL2: 0.0076847452 | AM2: 2 | AN2: 2 | AO2: 0 | AP2: 0 | AQ2: 0 | AR2: 0 | AS2: -1 | AT2: 1 | AU2: 0 | AV2: 0 | AW2: 0 | AX2: 0 | AY2: 835 | AZ2: 0.0195 | BA2: 1 | BB2: 1 | BC2: 1 | BD2: 1 | BE2: 1670 | BF2: 0.02 | BG2: 0 | BH2: 0 | BI2: 0 | BJ2: 0 | BK2: 0 | BL2: 0 | BM2: 0 | BN2: 0 | BO2: 0 | BP2: 0 | BQ2: 0 | BR2: 99999999 | BS2: 'L' | BT2: 'L' | BU2: 'L' | BV2: 'L' | BW2: 'L' | BX2: 'L' | BY2: 'L' | BZ2: 'L' | CA2: 0 | CB2: 0 | CC2: 'L' | CD2: 'L' | CE2: 'L' | CF2: 'L' | CG2: 'L' | CH2: 0 | CI2: 0 | CJ2: 0 | CK2: 0 | CL2: 'L' | CM2: 'L' | CN2: 'L' | CO2: 'L' | CP2: 0 | CQ2: 0 | CR2: 0 | CS2: 0 | CT2: 0 | CU2: 0 | CV2: 0 | CW2: 'L' | CX2: 'L' | CY2: 'L' | CZ2: 'L' | DA2: 0 | DB2: 'L' | DC2: 0 | DD2: 0 | DE2: 'L' | DF2: 0 | DG2: 'L' | DH2: 0 | DI2: 0 | DJ2: 0 | DK2: 'L' | DL2: 'L' | DM2: 'L' | DN2: 'L' | DO2: 'L' | DP2: 'L' | DQ2: 'L' | DR2: 'L' | DS2: 'L' | DT2: 'L' | DU2: 'L' | DV2: 'L' | DW2: 'L' | DX2: 'L' | DY2: 'L' | DZ2: 'L' | EA2: 'L' | EB2: 'L' | EC2: 1.1368684e-13 | ED2: 0 | EE2: 0 | EF2: -1 | EG2: 0 | EH2: 0 | EI2: 0 | EJ2: 1.1368684e-13 | EK2: 0 | EL2: 5339 | EM2: 0 | EN2: 1.5955709e-12 | EO2: 0 | EP2: 0 | EQ2: 0 | ER2: 0 | ES2: 0 | ET2: 0 | EU2: 0 | EV2: 0 | EW2: 0 | EX2: 0 | EY2: 0 | EZ2: 0 | FA2: 0 | FB2: 0 | FC2: 0 | FD2: 0 | FE2: 0 | FF2: 0 | FG2: 0 | FH2: 0 | FI2: 0 | FJ2: 0 | FK2: 0 | FL2: -1 | FM2: 0 | FN2: 0 | FO2: 0 | FP2: 0 | FQ2: 0 | FR2: 0 | FS2: 0 | FT2: 0 | FU2: 0 | FV2: 1 | FW2: 0 | FX2: 0 | FY2: 0 | FZ2: 0 | GA2: 0 | GB2: 0 | GC2: 0 | GD2: 0 | GE2: 0 | GF2: 0 | GG2: 0 | GH2: 0 | GI2: 0 | GJ2: 5656 | GK2: 7987 | GL2: 0 | GM2: 0 | GN2: 0 | GO2: 15769 | GP2: 15769 | GQ2: 0 | GR2: 0 | GS2: 4480 | GT2: 4480 | GU2: 0 | GV2: 'Platoon_Tree' | GW2: 1 | GX2: 0 | GY2: 1720353965 | GZ2: 42.455 | HA2: 42.455 | HB2: 42.455 | HC2: 42.455 | HD2: 42.455 | HE2: 0 | HF2: 0.017999887 | HG2: 0.0076847452 | HH2: 2 | HI2: 2 | HJ2: 0 | HK2: 0 | HL2: 0 | HM2: 0 | HN2: -1 | HO2: 1 | HP2: 0 | HQ2: 0 | HR2: 0 | HS2: 0 | HT2: 835 | HU2: 0.0195 | HV2: 1 | HW2: 1 | HX2: 1 | HY2: 1 | HZ2: 1670 | IA2: 0.02 | IB2: 0 | IC2: 0 | ID2: 0 | IE2: 0 | IF2: 0 | IG2: 0 | IH2: 0 | II2: 0 | IJ2: 0 | IK2: 0 | IL2: 0 | IM2: 99999999 | IN2: 'L' | IO2: 'L' | IP2: 'L' | IQ2: 'L' | IR2: 'L' | IS2: 'L' | IT2: 'L' | IU2: 'L' | IV2: 0 | IW2: 0 | IX2: 'L' | IY2: 'L' | IZ2: 'L' | JA2: 'L' | JB2: 'L' | JC2: 0 | JD2: 0 | JE2: 0 | JF2: 0 | JG2: 'L' | JH2: 'L' | JI2: 'L' | JJ2: 'L' | JK2: 0 | JL2: 0 | JM2: 0 | JN2: 0 | JO2: 0 | JP2: 0 | JQ2: 0 | JR2: 'L' | JS2: 'L' | JT2: 'L' | JU2: 'L' | JV2: 0 | JW2: 'L' | JX2: 0 | JY2: 0 | JZ2: 'L' | KA2: 0 | KB2: 'L' | KC2: 0 | KD2: 0 | KE2: 0 | KF2: 'L' | KG2: 'L' | KH2: 'L' | KI2: 'L' | KJ2: 'L' | KK2: 'L' | KL2: 'L' | KM2: 'L' | KN2: 'L' | KO2: 'L' | KP2: 'L' | KQ2: 'L' | KR2: 'L' | KS2: 'L' | KT2: 'L' | KU2: 'L' | KV2: 'L' | KW2: 'L' | KX2: 1.1368684e-13 | KY2: 0 | KZ2: 0 | LA2: -1 | LB2: 0 | LC2: 0 | LD2: 0 | LE2: 1.1368684e-13 | LF2: 0 | LG2: 5339 | LH2: 0 | LI2: 1.5955709e-12 | LJ2: 0 | LK2: 0 | LL2: 0 | LM2: 0 | LN2: 0 | LO2: 0 | LP2: 0 | LQ2: 0 | LR2: 0 | LS2: 0 | LT2: 0 | LU2: 0 | LV2: 0 | LW2: 0 | LX2: 0 | LY2: 0 | LZ2: 0 | MA2: 0 | MB2: 0 | MC2: 0 | MD2: 0 | ME2: 0 | MF2: 0 | MG2: -1 | MH2: 0 | MI2: 0 | MJ2: 0 | MK2: 0 | ML2: 0 | MM2: 0 | MN2: 0 | MO2: 0 | MP2: 0 | MQ2: 1 | MR2: 0 | MS2: 0 | MT2: 0 | MU2: 0 | MV2: 0 | MW2: 0 | MX2: 0 | MY2: 0 | MZ2: 0 | NA2: 0 | NB2: 0 | NC2: 0 | ND2: 0 | NE2: 'line']
